2015-08-27 10:18:29
Traceback (most recent call last):
  File "/Users/wbond/Library/Application Support/Sublime Text 3/Packages/SFTP/sftp/ftp_transport.py", line 189, in handle_ftp_error
  File "/Users/wbond/Library/Application Support/Sublime Text 3/Packages/SFTP/sftp/ftp_transport.py", line 803, in do_put
  File "/Users/wbond/Library/Application Support/Sublime Text 3/Packages/SFTP/sftp/ftplib2.py", line 552, in storbinary
  File "/Users/wbond/Library/Application Support/Sublime Text 3/Packages/SFTP/sftp/ftplib2.py", line 454, in transfercmd
  File "/Users/wbond/Library/Application Support/Sublime Text 3/Packages/SFTP/sftp/ftplib2.py", line 412, in ntransfercmd
  File "./socket.py", line 435, in create_connection
  File "./socket.py", line 426, in create_connection
ConnectionRefusedError: [Errno 61] Connection refused

During handling of the above exception, another exception occurred:

Traceback (most recent call last):
  File "/Users/wbond/Library/Application Support/Sublime Text 3/Packages/SFTP/sftp/threads.py", line 15, in run_with_except_hook
  File "/Users/wbond/Library/Application Support/Sublime Text 3/Packages/SFTP/sftp/threads.py", line 113, in handler
  File "/Users/wbond/Library/Application Support/Sublime Text 3/Packages/SFTP/sftp/commands.py", line 332, in run
  File "/Users/wbond/Library/Application Support/Sublime Text 3/Packages/SFTP/sftp/commands.py", line 480, in do_operation
  File "/Users/wbond/Library/Application Support/Sublime Text 3/Packages/SFTP/sftp/file_transfer.py", line 34, in handler
  File "/Users/wbond/Library/Application Support/Sublime Text 3/Packages/SFTP/sftp/ftp_transport.py", line 839, in put
  File "/Users/wbond/Library/Application Support/Sublime Text 3/Packages/SFTP/sftp/ftp_transport.py", line 357, in handle_ftp_error
SFTP.sftp.errors.ConnectionError: Connection refused
2015-08-27 10:18:41
Traceback (most recent call last):
  File "/Users/wbond/Library/Application Support/Sublime Text 3/Packages/SFTP/sftp/ftp_transport.py", line 189, in handle_ftp_error
  File "/Users/wbond/Library/Application Support/Sublime Text 3/Packages/SFTP/sftp/ftp_transport.py", line 803, in do_put
  File "/Users/wbond/Library/Application Support/Sublime Text 3/Packages/SFTP/sftp/ftplib2.py", line 552, in storbinary
  File "/Users/wbond/Library/Application Support/Sublime Text 3/Packages/SFTP/sftp/ftplib2.py", line 454, in transfercmd
  File "/Users/wbond/Library/Application Support/Sublime Text 3/Packages/SFTP/sftp/ftplib2.py", line 412, in ntransfercmd
  File "./socket.py", line 435, in create_connection
  File "./socket.py", line 426, in create_connection
ConnectionRefusedError: [Errno 61] Connection refused

During handling of the above exception, another exception occurred:

Traceback (most recent call last):
  File "/Users/wbond/Library/Application Support/Sublime Text 3/Packages/SFTP/sftp/threads.py", line 15, in run_with_except_hook
  File "/Users/wbond/Library/Application Support/Sublime Text 3/Packages/SFTP/sftp/threads.py", line 113, in handler
  File "/Users/wbond/Library/Application Support/Sublime Text 3/Packages/SFTP/sftp/commands.py", line 332, in run
  File "/Users/wbond/Library/Application Support/Sublime Text 3/Packages/SFTP/sftp/commands.py", line 480, in do_operation
  File "/Users/wbond/Library/Application Support/Sublime Text 3/Packages/SFTP/sftp/file_transfer.py", line 34, in handler
  File "/Users/wbond/Library/Application Support/Sublime Text 3/Packages/SFTP/sftp/ftp_transport.py", line 839, in put
  File "/Users/wbond/Library/Application Support/Sublime Text 3/Packages/SFTP/sftp/ftp_transport.py", line 357, in handle_ftp_error
SFTP.sftp.errors.ConnectionError: Connection refused
